================================================ FAILURES SHORT STACK ================================================
__________________ [doctest] transformers.models.van.modeling_van.VanForImageClassification.forward __________________
562 
563     ```python
564     >>> from transformers import AutoFeatureExtractor, VanForImageClassification
565     >>> import torch
566     >>> from datasets import load_dataset
567 
568     >>> dataset = load_dataset("huggingface/cats-image")
569     >>> image = dataset["test"]["image"][0]
570 
571     >>> feature_extractor = AutoFeatureExtractor.from_pretrained("van-base")
UNEXPECTED EXCEPTION: OSError("van-base is not a local folder and is not a valid model identifier listed on 'https://huggingface.co/models'\nIf this is a private repository, make sure to pass a token having permission to this repo with `use_auth_token` or log in with `huggingface-cli login` and pass `use_auth_token=True`.")
Traceback (most recent call last):
  File "/home/patrick/transformers/src/transformers/feature_extraction_utils.py", line 404, in get_feature_extractor_dict
    resolved_feature_extractor_file = cached_path(
  File "/home/patrick/transformers/src/transformers/file_utils.py", line 1947, in cached_path
    output_path = get_from_cache(
  File "/home/patrick/transformers/src/transformers/file_utils.py", line 2151, in get_from_cache
    _raise_for_status(r)
  File "/home/patrick/transformers/src/transformers/file_utils.py", line 2072, in _raise_for_status
    raise RepositoryNotFoundError(f"404 Client Error: Repository Not Found for url: {request.url}")
transformers.file_utils.RepositoryNotFoundError: 404 Client Error: Repository Not Found for url: https://huggingface.co/van-base/resolve/main/preprocessor_config.json
During handling of the above exception, another exception occurred:
Traceback (most recent call last):
  File "/home/patrick/anaconda3/envs/hf/lib/python3.9/doctest.py", line 1336, in __run
    exec(compile(example.source, filename, "single",
  File "<doctest transformers.models.van.modeling_van.VanForImageClassification.forward[5]>", line 1, in <module>
  File "/home/patrick/transformers/src/transformers/models/auto/feature_extraction_auto.py", line 264, in from_pretrained
    config_dict, _ = FeatureExtractionMixin.get_feature_extractor_dict(pretrained_model_name_or_path, **kwargs)
  File "/home/patrick/transformers/src/transformers/feature_extraction_utils.py", line 416, in get_feature_extractor_dict
    raise EnvironmentError(
OSError: van-base is not a local folder and is not a valid model identifier listed on 'https://huggingface.co/models'
If this is a private repository, make sure to pass a token having permission to this repo with `use_auth_token` or log in with `huggingface-cli login` and pass `use_auth_token=True`.
/home/patrick/transformers/src/transformers/models/van/modeling_van.py:571: UnexpectedException
563     ```python
564     >>> from transformers import AutoFeatureExtractor, VanForImageClassification
565     >>> import torch
566     >>> from datasets import load_dataset
567 
568     >>> dataset = load_dataset("huggingface/cats-image")
569     >>> image = dataset["test"]["image"][0]
570 
571     >>> feature_extractor = AutoFeatureExtractor.from_pretrained("van-base")
572     >>> model = VanForImageClassification.from_pretrained("van-base")
UNEXPECTED EXCEPTION: OSError("van-base is not a local folder and is not a valid model identifier listed on 'https://huggingface.co/models'\nIf this is a private repository, make sure to pass a token having permission to this repo with `use_auth_token` or log in with `huggingface-cli login` and pass `use_auth_token=True`.")
Traceback (most recent call last):
  File "/home/patrick/transformers/src/transformers/configuration_utils.py", line 595, in _get_config_dict
    resolved_config_file = cached_path(
  File "/home/patrick/transformers/src/transformers/file_utils.py", line 1947, in cached_path
    output_path = get_from_cache(
  File "/home/patrick/transformers/src/transformers/file_utils.py", line 2151, in get_from_cache
    _raise_for_status(r)
  File "/home/patrick/transformers/src/transformers/file_utils.py", line 2072, in _raise_for_status
    raise RepositoryNotFoundError(f"404 Client Error: Repository Not Found for url: {request.url}")
transformers.file_utils.RepositoryNotFoundError: 404 Client Error: Repository Not Found for url: https://huggingface.co/van-base/resolve/main/config.json
During handling of the above exception, another exception occurred:
Traceback (most recent call last):
  File "/home/patrick/anaconda3/envs/hf/lib/python3.9/doctest.py", line 1336, in __run
    exec(compile(example.source, filename, "single",
  File "<doctest transformers.models.van.modeling_van.VanForImageClassification.forward[6]>", line 1, in <module>
  File "/home/patrick/transformers/src/transformers/modeling_utils.py", line 1279, in from_pretrained
    config, model_kwargs = cls.config_class.from_pretrained(
  File "/home/patrick/transformers/src/transformers/configuration_utils.py", line 520, in from_pretrained
    config_dict, kwargs = cls.get_config_dict(pretrained_model_name_or_path, **kwargs)
  File "/home/patrick/transformers/src/transformers/configuration_utils.py", line 547, in get_config_dict
    config_dict, kwargs = cls._get_config_dict(pretrained_model_name_or_path, **kwargs)
  File "/home/patrick/transformers/src/transformers/configuration_utils.py", line 607, in _get_config_dict
    raise EnvironmentError(
OSError: van-base is not a local folder and is not a valid model identifier listed on 'https://huggingface.co/models'
If this is a private repository, make sure to pass a token having permission to this repo with `use_auth_token` or log in with `huggingface-cli login` and pass `use_auth_token=True`.
/home/patrick/transformers/src/transformers/models/van/modeling_van.py:572: UnexpectedException
565     >>> import torch
566     >>> from datasets import load_dataset
567 
568     >>> dataset = load_dataset("huggingface/cats-image")
569     >>> image = dataset["test"]["image"][0]
570 
571     >>> feature_extractor = AutoFeatureExtractor.from_pretrained("van-base")
572     >>> model = VanForImageClassification.from_pretrained("van-base")
573 
574     >>> inputs = feature_extractor(image, return_tensors="pt")
UNEXPECTED EXCEPTION: NameError("name 'feature_extractor' is not defined")
Traceback (most recent call last):
  File "/home/patrick/anaconda3/envs/hf/lib/python3.9/doctest.py", line 1336, in __run
    exec(compile(example.source, filename, "single",
  File "<doctest transformers.models.van.modeling_van.VanForImageClassification.forward[7]>", line 1, in <module>
NameError: name 'feature_extractor' is not defined
/home/patrick/transformers/src/transformers/models/van/modeling_van.py:574: UnexpectedException
567 
568     >>> dataset = load_dataset("huggingface/cats-image")
569     >>> image = dataset["test"]["image"][0]
570 
571     >>> feature_extractor = AutoFeatureExtractor.from_pretrained("van-base")
572     >>> model = VanForImageClassification.from_pretrained("van-base")
573 
574     >>> inputs = feature_extractor(image, return_tensors="pt")
575 
576     >>> with torch.no_grad():
UNEXPECTED EXCEPTION: NameError("name 'model' is not defined")
Traceback (most recent call last):
  File "/home/patrick/anaconda3/envs/hf/lib/python3.9/doctest.py", line 1336, in __run
    exec(compile(example.source, filename, "single",
  File "<doctest transformers.models.van.modeling_van.VanForImageClassification.forward[8]>", line 2, in <module>
NameError: name 'model' is not defined
/home/patrick/transformers/src/transformers/models/van/modeling_van.py:576: UnexpectedException
571     >>> feature_extractor = AutoFeatureExtractor.from_pretrained("van-base")
572     >>> model = VanForImageClassification.from_pretrained("van-base")
573 
574     >>> inputs = feature_extractor(image, return_tensors="pt")
575 
576     >>> with torch.no_grad():
577     ...     logits = model(**inputs).logits
578 
579     >>> # model predicts one of the 1000 ImageNet classes
580     >>> predicted_label = logits.argmax(-1).item()
UNEXPECTED EXCEPTION: NameError("name 'logits' is not defined")
Traceback (most recent call last):
  File "/home/patrick/anaconda3/envs/hf/lib/python3.9/doctest.py", line 1336, in __run
    exec(compile(example.source, filename, "single",
  File "<doctest transformers.models.van.modeling_van.VanForImageClassification.forward[9]>", line 1, in <module>
NameError: name 'logits' is not defined
/home/patrick/transformers/src/transformers/models/van/modeling_van.py:580: UnexpectedException
572     >>> model = VanForImageClassification.from_pretrained("van-base")
573 
574     >>> inputs = feature_extractor(image, return_tensors="pt")
575 
576     >>> with torch.no_grad():
577     ...     logits = model(**inputs).logits
578 
579     >>> # model predicts one of the 1000 ImageNet classes
580     >>> predicted_label = logits.argmax(-1).item()
581     >>> print(model.config.id2label[predicted_label])
UNEXPECTED EXCEPTION: NameError("name 'model' is not defined")
Traceback (most recent call last):
  File "/home/patrick/anaconda3/envs/hf/lib/python3.9/doctest.py", line 1336, in __run
    exec(compile(example.source, filename, "single",
  File "<doctest transformers.models.van.modeling_van.VanForImageClassification.forward[10]>", line 1, in <module>
NameError: name 'model' is not defined
/home/patrick/transformers/src/transformers/models/van/modeling_van.py:581: UnexpectedException
__________________________ [doctest] transformers.models.van.modeling_van.VanModel.forward ___________________________
539     >>> feature_extractor = AutoFeatureExtractor.from_pretrained("Visual-Attention-Network/van-base")
540     >>> model = VanModel.from_pretrained("Visual-Attention-Network/van-base")
541 
542     >>> inputs = feature_extractor(image, return_tensors="pt")
543 
544     >>> with torch.no_grad():
545     ...     outputs = model(**inputs)
546 
547     >>> last_hidden_states = outputs.last_hidden_state
548     >>> list(last_hidden_states.shape)
Expected:
    [1, 512, 7, 7]
    ```
Got:
    [1, 512, 7, 7]

/home/patrick/transformers/src/transformers/models/van/modeling_van.py:548: DocTestFailure
_____________ [doctest] transformers.models.resnet.modeling_resnet.ResNetForImageClassification.forward ______________
435 
436     ```python
437     >>> from transformers import AutoFeatureExtractor, ResNetForImageClassification
438     >>> import torch
439     >>> from datasets import load_dataset
440 
441     >>> dataset = load_dataset("huggingface/cats-image")
442     >>> image = dataset["test"]["image"][0]
443 
444     >>> feature_extractor = AutoFeatureExtractor.from_pretrained("")
UNEXPECTED EXCEPTION: OSError("We couldn't connect to 'https://huggingface.co/' to load this model and it looks like  is not the path to a directory conaining a preprocessor_config.json file.\nCheckout your internet connection or see how to run the library in offline mode at 'https://huggingface.co/docs/transformers/installation#offline-mode'.")
Traceback (most recent call last):
  File "/home/patrick/transformers/src/transformers/feature_extraction_utils.py", line 404, in get_feature_extractor_dict
    resolved_feature_extractor_file = cached_path(
  File "/home/patrick/transformers/src/transformers/file_utils.py", line 1947, in cached_path
    output_path = get_from_cache(
  File "/home/patrick/transformers/src/transformers/file_utils.py", line 2151, in get_from_cache
    _raise_for_status(r)
  File "/home/patrick/transformers/src/transformers/file_utils.py", line 2078, in _raise_for_status
    request.raise_for_status()
  File "/home/patrick/anaconda3/envs/hf/lib/python3.9/site-packages/requests/models.py", line 960, in raise_for_status
    raise HTTPError(http_error_msg, response=self)
requests.exceptions.HTTPError: 404 Client Error: Not Found for url: https://huggingface.co//resolve/main/preprocessor_config.json
During handling of the above exception, another exception occurred:
Traceback (most recent call last):
  File "/home/patrick/anaconda3/envs/hf/lib/python3.9/doctest.py", line 1336, in __run
    exec(compile(example.source, filename, "single",
  File "<doctest transformers.models.resnet.modeling_resnet.ResNetForImageClassification.forward[5]>", line 1, in <module>
  File "/home/patrick/transformers/src/transformers/models/auto/feature_extraction_auto.py", line 264, in from_pretrained
    config_dict, _ = FeatureExtractionMixin.get_feature_extractor_dict(pretrained_model_name_or_path, **kwargs)
  File "/home/patrick/transformers/src/transformers/feature_extraction_utils.py", line 433, in get_feature_extractor_dict
    raise EnvironmentError(
OSError: We couldn't connect to 'https://huggingface.co/' to load this model and it looks like  is not the path to a directory conaining a preprocessor_config.json file.
Checkout your internet connection or see how to run the library in offline mode at 'https://huggingface.co/docs/transformers/installation#offline-mode'.
/home/patrick/transformers/src/transformers/models/resnet/modeling_resnet.py:444: UnexpectedException
436     ```python
437     >>> from transformers import AutoFeatureExtractor, ResNetForImageClassification
438     >>> import torch
439     >>> from datasets import load_dataset
440 
441     >>> dataset = load_dataset("huggingface/cats-image")
442     >>> image = dataset["test"]["image"][0]
443 
444     >>> feature_extractor = AutoFeatureExtractor.from_pretrained("")
445     >>> model = ResNetForImageClassification.from_pretrained("")
UNEXPECTED EXCEPTION: OSError("We couldn't connect to 'https://huggingface.co/' to load this model and it looks like  is not the path to a directory containing a config.json file.\nCheckout your internet connection or see how to run the library in offline mode at 'https://huggingface.co/docs/transformers/installation#offline-mode'.")
Traceback (most recent call last):
  File "/home/patrick/transformers/src/transformers/configuration_utils.py", line 595, in _get_config_dict
    resolved_config_file = cached_path(
  File "/home/patrick/transformers/src/transformers/file_utils.py", line 1947, in cached_path
    output_path = get_from_cache(
  File "/home/patrick/transformers/src/transformers/file_utils.py", line 2151, in get_from_cache
    _raise_for_status(r)
  File "/home/patrick/transformers/src/transformers/file_utils.py", line 2078, in _raise_for_status
    request.raise_for_status()
  File "/home/patrick/anaconda3/envs/hf/lib/python3.9/site-packages/requests/models.py", line 960, in raise_for_status
    raise HTTPError(http_error_msg, response=self)
requests.exceptions.HTTPError: 404 Client Error: Not Found for url: https://huggingface.co//resolve/main/config.json
During handling of the above exception, another exception occurred:
Traceback (most recent call last):
  File "/home/patrick/anaconda3/envs/hf/lib/python3.9/doctest.py", line 1336, in __run
    exec(compile(example.source, filename, "single",
  File "<doctest transformers.models.resnet.modeling_resnet.ResNetForImageClassification.forward[6]>", line 1, in <module>
  File "/home/patrick/transformers/src/transformers/modeling_utils.py", line 1279, in from_pretrained
    config, model_kwargs = cls.config_class.from_pretrained(
  File "/home/patrick/transformers/src/transformers/configuration_utils.py", line 520, in from_pretrained
    config_dict, kwargs = cls.get_config_dict(pretrained_model_name_or_path, **kwargs)
  File "/home/patrick/transformers/src/transformers/configuration_utils.py", line 547, in get_config_dict
    config_dict, kwargs = cls._get_config_dict(pretrained_model_name_or_path, **kwargs)
  File "/home/patrick/transformers/src/transformers/configuration_utils.py", line 624, in _get_config_dict
    raise EnvironmentError(
OSError: We couldn't connect to 'https://huggingface.co/' to load this model and it looks like  is not the path to a directory containing a config.json file.
Checkout your internet connection or see how to run the library in offline mode at 'https://huggingface.co/docs/transformers/installation#offline-mode'.
/home/patrick/transformers/src/transformers/models/resnet/modeling_resnet.py:445: UnexpectedException
438     >>> import torch
439     >>> from datasets import load_dataset
440 
441     >>> dataset = load_dataset("huggingface/cats-image")
442     >>> image = dataset["test"]["image"][0]
443 
444     >>> feature_extractor = AutoFeatureExtractor.from_pretrained("")
445     >>> model = ResNetForImageClassification.from_pretrained("")
446 
447     >>> inputs = feature_extractor(image, return_tensors="pt")
UNEXPECTED EXCEPTION: NameError("name 'feature_extractor' is not defined")
Traceback (most recent call last):
  File "/home/patrick/anaconda3/envs/hf/lib/python3.9/doctest.py", line 1336, in __run
    exec(compile(example.source, filename, "single",
  File "<doctest transformers.models.resnet.modeling_resnet.ResNetForImageClassification.forward[7]>", line 1, in <module>
NameError: name 'feature_extractor' is not defined
/home/patrick/transformers/src/transformers/models/resnet/modeling_resnet.py:447: UnexpectedException
440 
441     >>> dataset = load_dataset("huggingface/cats-image")
442     >>> image = dataset["test"]["image"][0]
443 
444     >>> feature_extractor = AutoFeatureExtractor.from_pretrained("")
445     >>> model = ResNetForImageClassification.from_pretrained("")
446 
447     >>> inputs = feature_extractor(image, return_tensors="pt")
448 
449     >>> with torch.no_grad():
UNEXPECTED EXCEPTION: NameError("name 'model' is not defined")
Traceback (most recent call last):
  File "/home/patrick/anaconda3/envs/hf/lib/python3.9/doctest.py", line 1336, in __run
    exec(compile(example.source, filename, "single",
  File "<doctest transformers.models.resnet.modeling_resnet.ResNetForImageClassification.forward[8]>", line 2, in <module>
NameError: name 'model' is not defined
/home/patrick/transformers/src/transformers/models/resnet/modeling_resnet.py:449: UnexpectedException
444     >>> feature_extractor = AutoFeatureExtractor.from_pretrained("")
445     >>> model = ResNetForImageClassification.from_pretrained("")
446 
447     >>> inputs = feature_extractor(image, return_tensors="pt")
448 
449     >>> with torch.no_grad():
450     ...     logits = model(**inputs).logits
451 
452     >>> # model predicts one of the 1000 ImageNet classes
453     >>> predicted_label = logits.argmax(-1).item()
UNEXPECTED EXCEPTION: NameError("name 'logits' is not defined")
Traceback (most recent call last):
  File "/home/patrick/anaconda3/envs/hf/lib/python3.9/doctest.py", line 1336, in __run
    exec(compile(example.source, filename, "single",
  File "<doctest transformers.models.resnet.modeling_resnet.ResNetForImageClassification.forward[9]>", line 1, in <module>
NameError: name 'logits' is not defined
/home/patrick/transformers/src/transformers/models/resnet/modeling_resnet.py:453: UnexpectedException
445     >>> model = ResNetForImageClassification.from_pretrained("")
446 
447     >>> inputs = feature_extractor(image, return_tensors="pt")
448 
449     >>> with torch.no_grad():
450     ...     logits = model(**inputs).logits
451 
452     >>> # model predicts one of the 1000 ImageNet classes
453     >>> predicted_label = logits.argmax(-1).item()
454     >>> print(model.config.id2label[predicted_label])
UNEXPECTED EXCEPTION: NameError("name 'model' is not defined")
Traceback (most recent call last):
  File "/home/patrick/anaconda3/envs/hf/lib/python3.9/doctest.py", line 1336, in __run
    exec(compile(example.source, filename, "single",
  File "<doctest transformers.models.resnet.modeling_resnet.ResNetForImageClassification.forward[10]>", line 1, in <module>
NameError: name 'model' is not defined
/home/patrick/transformers/src/transformers/models/resnet/modeling_resnet.py:454: UnexpectedException
______________________ [doctest] transformers.models.resnet.modeling_resnet.ResNetModel.forward ______________________
393 
394     ```python
395     >>> from transformers import AutoFeatureExtractor, ResNetModel
396     >>> import torch
397     >>> from datasets import load_dataset
398 
399     >>> dataset = load_dataset("huggingface/cats-image")
400     >>> image = dataset["test"]["image"][0]
401 
402     >>> feature_extractor = AutoFeatureExtractor.from_pretrained("")
UNEXPECTED EXCEPTION: OSError("We couldn't connect to 'https://huggingface.co/' to load this model and it looks like  is not the path to a directory conaining a preprocessor_config.json file.\nCheckout your internet connection or see how to run the library in offline mode at 'https://huggingface.co/docs/transformers/installation#offline-mode'.")
Traceback (most recent call last):
  File "/home/patrick/transformers/src/transformers/feature_extraction_utils.py", line 404, in get_feature_extractor_dict
    resolved_feature_extractor_file = cached_path(
  File "/home/patrick/transformers/src/transformers/file_utils.py", line 1947, in cached_path
    output_path = get_from_cache(
  File "/home/patrick/transformers/src/transformers/file_utils.py", line 2151, in get_from_cache
    _raise_for_status(r)
  File "/home/patrick/transformers/src/transformers/file_utils.py", line 2078, in _raise_for_status
    request.raise_for_status()
  File "/home/patrick/anaconda3/envs/hf/lib/python3.9/site-packages/requests/models.py", line 960, in raise_for_status
    raise HTTPError(http_error_msg, response=self)
requests.exceptions.HTTPError: 404 Client Error: Not Found for url: https://huggingface.co//resolve/main/preprocessor_config.json
During handling of the above exception, another exception occurred:
Traceback (most recent call last):
  File "/home/patrick/anaconda3/envs/hf/lib/python3.9/doctest.py", line 1336, in __run
    exec(compile(example.source, filename, "single",
  File "<doctest transformers.models.resnet.modeling_resnet.ResNetModel.forward[5]>", line 1, in <module>
  File "/home/patrick/transformers/src/transformers/models/auto/feature_extraction_auto.py", line 264, in from_pretrained
    config_dict, _ = FeatureExtractionMixin.get_feature_extractor_dict(pretrained_model_name_or_path, **kwargs)
  File "/home/patrick/transformers/src/transformers/feature_extraction_utils.py", line 433, in get_feature_extractor_dict
    raise EnvironmentError(
OSError: We couldn't connect to 'https://huggingface.co/' to load this model and it looks like  is not the path to a directory conaining a preprocessor_config.json file.
Checkout your internet connection or see how to run the library in offline mode at 'https://huggingface.co/docs/transformers/installation#offline-mode'.
/home/patrick/transformers/src/transformers/models/resnet/modeling_resnet.py:402: UnexpectedException
394     ```python
395     >>> from transformers import AutoFeatureExtractor, ResNetModel
396     >>> import torch
397     >>> from datasets import load_dataset
398 
399     >>> dataset = load_dataset("huggingface/cats-image")
400     >>> image = dataset["test"]["image"][0]
401 
402     >>> feature_extractor = AutoFeatureExtractor.from_pretrained("")
403     >>> model = ResNetModel.from_pretrained("")
UNEXPECTED EXCEPTION: OSError("We couldn't connect to 'https://huggingface.co/' to load this model and it looks like  is not the path to a directory containing a config.json file.\nCheckout your internet connection or see how to run the library in offline mode at 'https://huggingface.co/docs/transformers/installation#offline-mode'.")
Traceback (most recent call last):
  File "/home/patrick/transformers/src/transformers/configuration_utils.py", line 595, in _get_config_dict
    resolved_config_file = cached_path(
  File "/home/patrick/transformers/src/transformers/file_utils.py", line 1947, in cached_path
    output_path = get_from_cache(
  File "/home/patrick/transformers/src/transformers/file_utils.py", line 2151, in get_from_cache
    _raise_for_status(r)
  File "/home/patrick/transformers/src/transformers/file_utils.py", line 2078, in _raise_for_status
    request.raise_for_status()
  File "/home/patrick/anaconda3/envs/hf/lib/python3.9/site-packages/requests/models.py", line 960, in raise_for_status
    raise HTTPError(http_error_msg, response=self)
requests.exceptions.HTTPError: 404 Client Error: Not Found for url: https://huggingface.co//resolve/main/config.json
During handling of the above exception, another exception occurred:
Traceback (most recent call last):
  File "/home/patrick/anaconda3/envs/hf/lib/python3.9/doctest.py", line 1336, in __run
    exec(compile(example.source, filename, "single",
  File "<doctest transformers.models.resnet.modeling_resnet.ResNetModel.forward[6]>", line 1, in <module>
  File "/home/patrick/transformers/src/transformers/modeling_utils.py", line 1279, in from_pretrained
    config, model_kwargs = cls.config_class.from_pretrained(
  File "/home/patrick/transformers/src/transformers/configuration_utils.py", line 520, in from_pretrained
    config_dict, kwargs = cls.get_config_dict(pretrained_model_name_or_path, **kwargs)
  File "/home/patrick/transformers/src/transformers/configuration_utils.py", line 547, in get_config_dict
    config_dict, kwargs = cls._get_config_dict(pretrained_model_name_or_path, **kwargs)
  File "/home/patrick/transformers/src/transformers/configuration_utils.py", line 624, in _get_config_dict
    raise EnvironmentError(
OSError: We couldn't connect to 'https://huggingface.co/' to load this model and it looks like  is not the path to a directory containing a config.json file.
Checkout your internet connection or see how to run the library in offline mode at 'https://huggingface.co/docs/transformers/installation#offline-mode'.
/home/patrick/transformers/src/transformers/models/resnet/modeling_resnet.py:403: UnexpectedException
396     >>> import torch
397     >>> from datasets import load_dataset
398 
399     >>> dataset = load_dataset("huggingface/cats-image")
400     >>> image = dataset["test"]["image"][0]
401 
402     >>> feature_extractor = AutoFeatureExtractor.from_pretrained("")
403     >>> model = ResNetModel.from_pretrained("")
404 
405     >>> inputs = feature_extractor(image, return_tensors="pt")
UNEXPECTED EXCEPTION: NameError("name 'feature_extractor' is not defined")
Traceback (most recent call last):
  File "/home/patrick/anaconda3/envs/hf/lib/python3.9/doctest.py", line 1336, in __run
    exec(compile(example.source, filename, "single",
  File "<doctest transformers.models.resnet.modeling_resnet.ResNetModel.forward[7]>", line 1, in <module>
NameError: name 'feature_extractor' is not defined
/home/patrick/transformers/src/transformers/models/resnet/modeling_resnet.py:405: UnexpectedException
398 
399     >>> dataset = load_dataset("huggingface/cats-image")
400     >>> image = dataset["test"]["image"][0]
401 
402     >>> feature_extractor = AutoFeatureExtractor.from_pretrained("")
403     >>> model = ResNetModel.from_pretrained("")
404 
405     >>> inputs = feature_extractor(image, return_tensors="pt")
406 
407     >>> with torch.no_grad():
UNEXPECTED EXCEPTION: NameError("name 'model' is not defined")
Traceback (most recent call last):
  File "/home/patrick/anaconda3/envs/hf/lib/python3.9/doctest.py", line 1336, in __run
    exec(compile(example.source, filename, "single",
  File "<doctest transformers.models.resnet.modeling_resnet.ResNetModel.forward[8]>", line 2, in <module>
NameError: name 'model' is not defined
/home/patrick/transformers/src/transformers/models/resnet/modeling_resnet.py:407: UnexpectedException
401 
402     >>> feature_extractor = AutoFeatureExtractor.from_pretrained("")
403     >>> model = ResNetModel.from_pretrained("")
404 
405     >>> inputs = feature_extractor(image, return_tensors="pt")
406 
407     >>> with torch.no_grad():
408     ...     outputs = model(**inputs)
409 
410     >>> last_hidden_states = outputs.last_hidden_state
UNEXPECTED EXCEPTION: NameError("name 'outputs' is not defined")
Traceback (most recent call last):
  File "/home/patrick/anaconda3/envs/hf/lib/python3.9/doctest.py", line 1336, in __run
    exec(compile(example.source, filename, "single",
  File "<doctest transformers.models.resnet.modeling_resnet.ResNetModel.forward[9]>", line 1, in <module>
NameError: name 'outputs' is not defined
/home/patrick/transformers/src/transformers/models/resnet/modeling_resnet.py:410: UnexpectedException
402     >>> feature_extractor = AutoFeatureExtractor.from_pretrained("")
403     >>> model = ResNetModel.from_pretrained("")
404 
405     >>> inputs = feature_extractor(image, return_tensors="pt")
406 
407     >>> with torch.no_grad():
408     ...     outputs = model(**inputs)
409 
410     >>> last_hidden_states = outputs.last_hidden_state
411     >>> list(last_hidden_states.shape)
UNEXPECTED EXCEPTION: NameError("name 'last_hidden_states' is not defined")
Traceback (most recent call last):
  File "/home/patrick/anaconda3/envs/hf/lib/python3.9/doctest.py", line 1336, in __run
    exec(compile(example.source, filename, "single",
  File "<doctest transformers.models.resnet.modeling_resnet.ResNetModel.forward[10]>", line 1, in <module>
NameError: name 'last_hidden_states' is not defined
/home/patrick/transformers/src/transformers/models/resnet/modeling_resnet.py:411: UnexpectedException
